2024-10-31 13:50:19,314 django.request WARNING log Unauthorized: /api/v1/operations/
2024-10-31 13:50:24,176 django.request WARNING log Unauthorized: /api/v1/operations/
2024-10-31 13:55:12,898 django.request ERROR log Internal Server Error: /api/v1/operations/
Traceback (most recent call last):
  File "/home/igor/.cache/pypoetry/virtualenvs/financeapp-4bNmUlQi-py3.8/lib/python3.8/site-packages/django/db/backends/utils.py", line 89, in _execute
    return self.cursor.execute(sql, params)
psycopg2.errors.UndefinedColumn: column categories.is_fixed does not exist
LINE 1: ...tegories"."is_income", "categories"."is_outcome", "categorie...
                                                             ^


The above exception was the direct cause of the following exception:

Traceback (most recent call last):
  File "/home/igor/.cache/pypoetry/virtualenvs/financeapp-4bNmUlQi-py3.8/lib/python3.8/site-packages/django/core/handlers/exception.py", line 55, in inner
    response = get_response(request)
  File "/home/igor/.cache/pypoetry/virtualenvs/financeapp-4bNmUlQi-py3.8/lib/python3.8/site-packages/django/core/handlers/base.py", line 197, in _get_response
    response = wrapped_callback(request, *callback_args, **callback_kwargs)
  File "/home/igor/.cache/pypoetry/virtualenvs/financeapp-4bNmUlQi-py3.8/lib/python3.8/site-packages/django/views/decorators/csrf.py", line 56, in wrapper_view
    return view_func(*args, **kwargs)
  File "/home/igor/.cache/pypoetry/virtualenvs/financeapp-4bNmUlQi-py3.8/lib/python3.8/site-packages/django/views/generic/base.py", line 104, in view
    return self.dispatch(request, *args, **kwargs)
  File "/home/igor/.cache/pypoetry/virtualenvs/financeapp-4bNmUlQi-py3.8/lib/python3.8/site-packages/rest_framework/views.py", line 509, in dispatch
    response = self.handle_exception(exc)
  File "/home/igor/.cache/pypoetry/virtualenvs/financeapp-4bNmUlQi-py3.8/lib/python3.8/site-packages/rest_framework/views.py", line 469, in handle_exception
    self.raise_uncaught_exception(exc)
  File "/home/igor/.cache/pypoetry/virtualenvs/financeapp-4bNmUlQi-py3.8/lib/python3.8/site-packages/rest_framework/views.py", line 480, in raise_uncaught_exception
    raise exc
  File "/home/igor/.cache/pypoetry/virtualenvs/financeapp-4bNmUlQi-py3.8/lib/python3.8/site-packages/rest_framework/views.py", line 506, in dispatch
    response = handler(request, *args, **kwargs)
  File "/home/igor/.cache/pypoetry/virtualenvs/financeapp-4bNmUlQi-py3.8/lib/python3.8/site-packages/rest_framework/generics.py", line 246, in post
    return self.create(request, *args, **kwargs)
  File "/home/igor/.cache/pypoetry/virtualenvs/financeapp-4bNmUlQi-py3.8/lib/python3.8/site-packages/rest_framework/mixins.py", line 18, in create
    serializer.is_valid(raise_exception=True)
  File "/home/igor/.cache/pypoetry/virtualenvs/financeapp-4bNmUlQi-py3.8/lib/python3.8/site-packages/rest_framework/serializers.py", line 223, in is_valid
    self._validated_data = self.run_validation(self.initial_data)
  File "/home/igor/.cache/pypoetry/virtualenvs/financeapp-4bNmUlQi-py3.8/lib/python3.8/site-packages/rest_framework/serializers.py", line 442, in run_validation
    value = self.to_internal_value(data)
  File "/home/igor/.cache/pypoetry/virtualenvs/financeapp-4bNmUlQi-py3.8/lib/python3.8/site-packages/rest_framework/serializers.py", line 499, in to_internal_value
    validated_value = field.run_validation(primitive_value)
  File "/home/igor/.cache/pypoetry/virtualenvs/financeapp-4bNmUlQi-py3.8/lib/python3.8/site-packages/rest_framework/relations.py", line 155, in run_validation
    return super().run_validation(data)
  File "/home/igor/.cache/pypoetry/virtualenvs/financeapp-4bNmUlQi-py3.8/lib/python3.8/site-packages/rest_framework/fields.py", line 538, in run_validation
    value = self.to_internal_value(data)
  File "/home/igor/.cache/pypoetry/virtualenvs/financeapp-4bNmUlQi-py3.8/lib/python3.8/site-packages/rest_framework/relations.py", line 259, in to_internal_value
    return queryset.get(pk=data)
  File "/home/igor/.cache/pypoetry/virtualenvs/financeapp-4bNmUlQi-py3.8/lib/python3.8/site-packages/django/db/models/query.py", line 633, in get
    num = len(clone)
  File "/home/igor/.cache/pypoetry/virtualenvs/financeapp-4bNmUlQi-py3.8/lib/python3.8/site-packages/django/db/models/query.py", line 380, in __len__
    self._fetch_all()
  File "/home/igor/.cache/pypoetry/virtualenvs/financeapp-4bNmUlQi-py3.8/lib/python3.8/site-packages/django/db/models/query.py", line 1881, in _fetch_all
    self._result_cache = list(self._iterable_class(self))
  File "/home/igor/.cache/pypoetry/virtualenvs/financeapp-4bNmUlQi-py3.8/lib/python3.8/site-packages/django/db/models/query.py", line 91, in __iter__
    results = compiler.execute_sql(
  File "/home/igor/.cache/pypoetry/virtualenvs/financeapp-4bNmUlQi-py3.8/lib/python3.8/site-packages/django/db/models/sql/compiler.py", line 1562, in execute_sql
    cursor.execute(sql, params)
  File "/home/igor/.cache/pypoetry/virtualenvs/financeapp-4bNmUlQi-py3.8/lib/python3.8/site-packages/django/db/backends/utils.py", line 102, in execute
    return super().execute(sql, params)
  File "/home/igor/.cache/pypoetry/virtualenvs/financeapp-4bNmUlQi-py3.8/lib/python3.8/site-packages/django/db/backends/utils.py", line 67, in execute
    return self._execute_with_wrappers(
  File "/home/igor/.cache/pypoetry/virtualenvs/financeapp-4bNmUlQi-py3.8/lib/python3.8/site-packages/django/db/backends/utils.py", line 80, in _execute_with_wrappers
    return executor(sql, params, many, context)
  File "/home/igor/.cache/pypoetry/virtualenvs/financeapp-4bNmUlQi-py3.8/lib/python3.8/site-packages/django/db/backends/utils.py", line 89, in _execute
    return self.cursor.execute(sql, params)
  File "/home/igor/.cache/pypoetry/virtualenvs/financeapp-4bNmUlQi-py3.8/lib/python3.8/site-packages/django/db/utils.py", line 91, in __exit__
    raise dj_exc_value.with_traceback(traceback) from exc_value
  File "/home/igor/.cache/pypoetry/virtualenvs/financeapp-4bNmUlQi-py3.8/lib/python3.8/site-packages/django/db/backends/utils.py", line 89, in _execute
    return self.cursor.execute(sql, params)
django.db.utils.ProgrammingError: column categories.is_fixed does not exist
LINE 1: ...tegories"."is_income", "categories"."is_outcome", "categorie...
                                                             ^

2024-10-31 13:58:33,353 django.request ERROR log Internal Server Error: /api/v1/operations/
Traceback (most recent call last):
  File "/home/igor/.cache/pypoetry/virtualenvs/financeapp-4bNmUlQi-py3.8/lib/python3.8/site-packages/django/db/backends/utils.py", line 89, in _execute
    return self.cursor.execute(sql, params)
psycopg2.errors.NotNullViolation: null value in column "user_id" of relation "operations" violates not-null constraint
DETAIL:  Failing row contains (1, null, income, 15000.00, 5, null, 2024-10-20, 2024-10-31 10:58:33.221171+00, 2024-10-31 10:58:33.221201+00).


The above exception was the direct cause of the following exception:

Traceback (most recent call last):
  File "/home/igor/.cache/pypoetry/virtualenvs/financeapp-4bNmUlQi-py3.8/lib/python3.8/site-packages/django/core/handlers/exception.py", line 55, in inner
    response = get_response(request)
  File "/home/igor/.cache/pypoetry/virtualenvs/financeapp-4bNmUlQi-py3.8/lib/python3.8/site-packages/django/core/handlers/base.py", line 197, in _get_response
    response = wrapped_callback(request, *callback_args, **callback_kwargs)
  File "/home/igor/.cache/pypoetry/virtualenvs/financeapp-4bNmUlQi-py3.8/lib/python3.8/site-packages/django/views/decorators/csrf.py", line 56, in wrapper_view
    return view_func(*args, **kwargs)
  File "/home/igor/.cache/pypoetry/virtualenvs/financeapp-4bNmUlQi-py3.8/lib/python3.8/site-packages/django/views/generic/base.py", line 104, in view
    return self.dispatch(request, *args, **kwargs)
  File "/home/igor/.cache/pypoetry/virtualenvs/financeapp-4bNmUlQi-py3.8/lib/python3.8/site-packages/rest_framework/views.py", line 509, in dispatch
    response = self.handle_exception(exc)
  File "/home/igor/.cache/pypoetry/virtualenvs/financeapp-4bNmUlQi-py3.8/lib/python3.8/site-packages/rest_framework/views.py", line 469, in handle_exception
    self.raise_uncaught_exception(exc)
  File "/home/igor/.cache/pypoetry/virtualenvs/financeapp-4bNmUlQi-py3.8/lib/python3.8/site-packages/rest_framework/views.py", line 480, in raise_uncaught_exception
    raise exc
  File "/home/igor/.cache/pypoetry/virtualenvs/financeapp-4bNmUlQi-py3.8/lib/python3.8/site-packages/rest_framework/views.py", line 506, in dispatch
    response = handler(request, *args, **kwargs)
  File "/home/igor/.cache/pypoetry/virtualenvs/financeapp-4bNmUlQi-py3.8/lib/python3.8/site-packages/rest_framework/generics.py", line 246, in post
    return self.create(request, *args, **kwargs)
  File "/home/igor/.cache/pypoetry/virtualenvs/financeapp-4bNmUlQi-py3.8/lib/python3.8/site-packages/rest_framework/mixins.py", line 19, in create
    self.perform_create(serializer)
  File "/home/igor/.cache/pypoetry/virtualenvs/financeapp-4bNmUlQi-py3.8/lib/python3.8/site-packages/rest_framework/mixins.py", line 24, in perform_create
    serializer.save()
  File "/home/igor/.cache/pypoetry/virtualenvs/financeapp-4bNmUlQi-py3.8/lib/python3.8/site-packages/rest_framework/serializers.py", line 208, in save
    self.instance = self.create(validated_data)
  File "/home/igor/.cache/pypoetry/virtualenvs/financeapp-4bNmUlQi-py3.8/lib/python3.8/site-packages/rest_framework/serializers.py", line 989, in create
    instance = ModelClass._default_manager.create(**validated_data)
  File "/home/igor/.cache/pypoetry/virtualenvs/financeapp-4bNmUlQi-py3.8/lib/python3.8/site-packages/django/db/models/manager.py", line 87, in manager_method
    return getattr(self.get_queryset(), name)(*args, **kwargs)
  File "/home/igor/.cache/pypoetry/virtualenvs/financeapp-4bNmUlQi-py3.8/lib/python3.8/site-packages/django/db/models/query.py", line 658, in create
    obj.save(force_insert=True, using=self.db)
  File "/home/igor/.cache/pypoetry/virtualenvs/financeapp-4bNmUlQi-py3.8/lib/python3.8/site-packages/django/db/models/base.py", line 814, in save
    self.save_base(
  File "/home/igor/.cache/pypoetry/virtualenvs/financeapp-4bNmUlQi-py3.8/lib/python3.8/site-packages/django/db/models/base.py", line 877, in save_base
    updated = self._save_table(
  File "/home/igor/.cache/pypoetry/virtualenvs/financeapp-4bNmUlQi-py3.8/lib/python3.8/site-packages/django/db/models/base.py", line 1020, in _save_table
    results = self._do_insert(
  File "/home/igor/.cache/pypoetry/virtualenvs/financeapp-4bNmUlQi-py3.8/lib/python3.8/site-packages/django/db/models/base.py", line 1061, in _do_insert
    return manager._insert(
  File "/home/igor/.cache/pypoetry/virtualenvs/financeapp-4bNmUlQi-py3.8/lib/python3.8/site-packages/django/db/models/manager.py", line 87, in manager_method
    return getattr(self.get_queryset(), name)(*args, **kwargs)
  File "/home/igor/.cache/pypoetry/virtualenvs/financeapp-4bNmUlQi-py3.8/lib/python3.8/site-packages/django/db/models/query.py", line 1805, in _insert
    return query.get_compiler(using=using).execute_sql(returning_fields)
  File "/home/igor/.cache/pypoetry/virtualenvs/financeapp-4bNmUlQi-py3.8/lib/python3.8/site-packages/django/db/models/sql/compiler.py", line 1822, in execute_sql
    cursor.execute(sql, params)
  File "/home/igor/.cache/pypoetry/virtualenvs/financeapp-4bNmUlQi-py3.8/lib/python3.8/site-packages/django/db/backends/utils.py", line 102, in execute
    return super().execute(sql, params)
  File "/home/igor/.cache/pypoetry/virtualenvs/financeapp-4bNmUlQi-py3.8/lib/python3.8/site-packages/django/db/backends/utils.py", line 67, in execute
    return self._execute_with_wrappers(
  File "/home/igor/.cache/pypoetry/virtualenvs/financeapp-4bNmUlQi-py3.8/lib/python3.8/site-packages/django/db/backends/utils.py", line 80, in _execute_with_wrappers
    return executor(sql, params, many, context)
  File "/home/igor/.cache/pypoetry/virtualenvs/financeapp-4bNmUlQi-py3.8/lib/python3.8/site-packages/django/db/backends/utils.py", line 89, in _execute
    return self.cursor.execute(sql, params)
  File "/home/igor/.cache/pypoetry/virtualenvs/financeapp-4bNmUlQi-py3.8/lib/python3.8/site-packages/django/db/utils.py", line 91, in __exit__
    raise dj_exc_value.with_traceback(traceback) from exc_value
  File "/home/igor/.cache/pypoetry/virtualenvs/financeapp-4bNmUlQi-py3.8/lib/python3.8/site-packages/django/db/backends/utils.py", line 89, in _execute
    return self.cursor.execute(sql, params)
django.db.utils.IntegrityError: null value in column "user_id" of relation "operations" violates not-null constraint
DETAIL:  Failing row contains (1, null, income, 15000.00, 5, null, 2024-10-20, 2024-10-31 10:58:33.221171+00, 2024-10-31 10:58:33.221201+00).

2024-11-04 11:49:05,397 django.request WARNING log Bad Request: /api/v1/categories/
2024-11-04 11:53:23,778 django.request ERROR log Internal Server Error: /api/v1/categories/
Traceback (most recent call last):
  File "/home/igor/.cache/pypoetry/virtualenvs/financeapp-4bNmUlQi-py3.8/lib/python3.8/site-packages/django/core/handlers/exception.py", line 55, in inner
    response = get_response(request)
  File "/home/igor/.cache/pypoetry/virtualenvs/financeapp-4bNmUlQi-py3.8/lib/python3.8/site-packages/django/core/handlers/base.py", line 197, in _get_response
    response = wrapped_callback(request, *callback_args, **callback_kwargs)
  File "/home/igor/.cache/pypoetry/virtualenvs/financeapp-4bNmUlQi-py3.8/lib/python3.8/site-packages/django/views/decorators/csrf.py", line 56, in wrapper_view
    return view_func(*args, **kwargs)
  File "/home/igor/.cache/pypoetry/virtualenvs/financeapp-4bNmUlQi-py3.8/lib/python3.8/site-packages/django/views/generic/base.py", line 104, in view
    return self.dispatch(request, *args, **kwargs)
  File "/home/igor/.cache/pypoetry/virtualenvs/financeapp-4bNmUlQi-py3.8/lib/python3.8/site-packages/rest_framework/views.py", line 509, in dispatch
    response = self.handle_exception(exc)
  File "/home/igor/.cache/pypoetry/virtualenvs/financeapp-4bNmUlQi-py3.8/lib/python3.8/site-packages/rest_framework/views.py", line 469, in handle_exception
    self.raise_uncaught_exception(exc)
  File "/home/igor/.cache/pypoetry/virtualenvs/financeapp-4bNmUlQi-py3.8/lib/python3.8/site-packages/rest_framework/views.py", line 480, in raise_uncaught_exception
    raise exc
  File "/home/igor/.cache/pypoetry/virtualenvs/financeapp-4bNmUlQi-py3.8/lib/python3.8/site-packages/rest_framework/views.py", line 506, in dispatch
    response = handler(request, *args, **kwargs)
  File "/home/igor/.cache/pypoetry/virtualenvs/financeapp-4bNmUlQi-py3.8/lib/python3.8/site-packages/rest_framework/generics.py", line 246, in post
    return self.create(request, *args, **kwargs)
  File "/home/igor/.cache/pypoetry/virtualenvs/financeapp-4bNmUlQi-py3.8/lib/python3.8/site-packages/rest_framework/mixins.py", line 19, in create
    self.perform_create(serializer)
  File "/home/igor/.cache/pypoetry/virtualenvs/financeapp-4bNmUlQi-py3.8/lib/python3.8/site-packages/rest_framework/mixins.py", line 24, in perform_create
    serializer.save()
  File "/home/igor/.cache/pypoetry/virtualenvs/financeapp-4bNmUlQi-py3.8/lib/python3.8/site-packages/rest_framework/serializers.py", line 208, in save
    self.instance = self.create(validated_data)
  File "/home/igor/Documents/FinanceApp/api/serializers/category.py", line 46, in create
    raise CategoryExistsError(
api.serializers.errors.CategoryExistsError: The category already exists.
2024-11-04 20:27:06,811 django.request WARNING log Unauthorized: /api/v1/categories/5/
2024-11-04 20:32:35,854 django.request WARNING log Not Found: /api/v1/categories/6/
2024-11-04 20:33:48,935 django.request WARNING log Not Found: /api/v1/categories/6/
2024-11-04 20:59:04,777 django.request ERROR log Internal Server Error: /api/v1/categories/8/
Traceback (most recent call last):
  File "/home/igor/.cache/pypoetry/virtualenvs/financeapp-4bNmUlQi-py3.8/lib/python3.8/site-packages/django/core/handlers/exception.py", line 55, in inner
    response = get_response(request)
  File "/home/igor/.cache/pypoetry/virtualenvs/financeapp-4bNmUlQi-py3.8/lib/python3.8/site-packages/django/core/handlers/base.py", line 197, in _get_response
    response = wrapped_callback(request, *callback_args, **callback_kwargs)
  File "/home/igor/.cache/pypoetry/virtualenvs/financeapp-4bNmUlQi-py3.8/lib/python3.8/site-packages/django/views/decorators/csrf.py", line 56, in wrapper_view
    return view_func(*args, **kwargs)
  File "/home/igor/.cache/pypoetry/virtualenvs/financeapp-4bNmUlQi-py3.8/lib/python3.8/site-packages/django/views/generic/base.py", line 104, in view
    return self.dispatch(request, *args, **kwargs)
  File "/home/igor/.cache/pypoetry/virtualenvs/financeapp-4bNmUlQi-py3.8/lib/python3.8/site-packages/rest_framework/views.py", line 509, in dispatch
    response = self.handle_exception(exc)
  File "/home/igor/.cache/pypoetry/virtualenvs/financeapp-4bNmUlQi-py3.8/lib/python3.8/site-packages/rest_framework/views.py", line 469, in handle_exception
    self.raise_uncaught_exception(exc)
  File "/home/igor/.cache/pypoetry/virtualenvs/financeapp-4bNmUlQi-py3.8/lib/python3.8/site-packages/rest_framework/views.py", line 480, in raise_uncaught_exception
    raise exc
  File "/home/igor/.cache/pypoetry/virtualenvs/financeapp-4bNmUlQi-py3.8/lib/python3.8/site-packages/rest_framework/views.py", line 506, in dispatch
    response = handler(request, *args, **kwargs)
  File "/home/igor/.cache/pypoetry/virtualenvs/financeapp-4bNmUlQi-py3.8/lib/python3.8/site-packages/rest_framework/generics.py", line 221, in delete
    return self.destroy(request, *args, **kwargs)
  File "/home/igor/Documents/FinanceApp/api/views/categories.py", line 64, in destroy
    raise CategoryWithOperationsError(
api.views.errors.CategoryWithOperationsError: Can not delete category with existing operations.
2024-11-04 21:02:43,033 django.request WARNING log Not Found: /api/v1/categories/9/
2024-11-04 21:09:24,992 django.request ERROR log Internal Server Error: /api/v1/categories/9/
Traceback (most recent call last):
  File "/home/igor/.cache/pypoetry/virtualenvs/financeapp-4bNmUlQi-py3.8/lib/python3.8/site-packages/django/core/handlers/exception.py", line 55, in inner
    response = get_response(request)
  File "/home/igor/.cache/pypoetry/virtualenvs/financeapp-4bNmUlQi-py3.8/lib/python3.8/site-packages/django/core/handlers/base.py", line 220, in _get_response
    response = response.render()
  File "/home/igor/.cache/pypoetry/virtualenvs/financeapp-4bNmUlQi-py3.8/lib/python3.8/site-packages/django/template/response.py", line 114, in render
    self.content = self.rendered_content
  File "/home/igor/.cache/pypoetry/virtualenvs/financeapp-4bNmUlQi-py3.8/lib/python3.8/site-packages/rest_framework/response.py", line 74, in rendered_content
    ret = renderer.render(self.data, accepted_media_type, context)
  File "/home/igor/.cache/pypoetry/virtualenvs/financeapp-4bNmUlQi-py3.8/lib/python3.8/site-packages/rest_framework/renderers.py", line 100, in render
    ret = json.dumps(
  File "/home/igor/.cache/pypoetry/virtualenvs/financeapp-4bNmUlQi-py3.8/lib/python3.8/site-packages/rest_framework/utils/json.py", line 25, in dumps
    return json.dumps(*args, **kwargs)
  File "/usr/lib/python3.8/json/__init__.py", line 234, in dumps
    return cls(
  File "/usr/lib/python3.8/json/encoder.py", line 199, in encode
    chunks = self.iterencode(o, _one_shot=True)
  File "/usr/lib/python3.8/json/encoder.py", line 257, in iterencode
    return _iterencode(o, 0)
  File "/home/igor/.cache/pypoetry/virtualenvs/financeapp-4bNmUlQi-py3.8/lib/python3.8/site-packages/rest_framework/utils/encoders.py", line 67, in default
    return super().default(obj)
  File "/usr/lib/python3.8/json/encoder.py", line 179, in default
    raise TypeError(f'Object of type {o.__class__.__name__} '
TypeError: Object of type Category is not JSON serializable
2024-11-04 21:20:06,842 django.request WARNING log Not Found: /api/v1/categories/9/
2024-11-04 21:20:25,081 django.request ERROR log Internal Server Error: /api/v1/categories/8/
Traceback (most recent call last):
  File "/home/igor/.cache/pypoetry/virtualenvs/financeapp-4bNmUlQi-py3.8/lib/python3.8/site-packages/django/core/handlers/exception.py", line 55, in inner
    response = get_response(request)
  File "/home/igor/.cache/pypoetry/virtualenvs/financeapp-4bNmUlQi-py3.8/lib/python3.8/site-packages/django/core/handlers/base.py", line 197, in _get_response
    response = wrapped_callback(request, *callback_args, **callback_kwargs)
  File "/home/igor/.cache/pypoetry/virtualenvs/financeapp-4bNmUlQi-py3.8/lib/python3.8/site-packages/django/views/decorators/csrf.py", line 56, in wrapper_view
    return view_func(*args, **kwargs)
  File "/home/igor/.cache/pypoetry/virtualenvs/financeapp-4bNmUlQi-py3.8/lib/python3.8/site-packages/django/views/generic/base.py", line 104, in view
    return self.dispatch(request, *args, **kwargs)
  File "/home/igor/.cache/pypoetry/virtualenvs/financeapp-4bNmUlQi-py3.8/lib/python3.8/site-packages/rest_framework/views.py", line 509, in dispatch
    response = self.handle_exception(exc)
  File "/home/igor/.cache/pypoetry/virtualenvs/financeapp-4bNmUlQi-py3.8/lib/python3.8/site-packages/rest_framework/views.py", line 469, in handle_exception
    self.raise_uncaught_exception(exc)
  File "/home/igor/.cache/pypoetry/virtualenvs/financeapp-4bNmUlQi-py3.8/lib/python3.8/site-packages/rest_framework/views.py", line 480, in raise_uncaught_exception
    raise exc
  File "/home/igor/.cache/pypoetry/virtualenvs/financeapp-4bNmUlQi-py3.8/lib/python3.8/site-packages/rest_framework/views.py", line 506, in dispatch
    response = handler(request, *args, **kwargs)
  File "/home/igor/.cache/pypoetry/virtualenvs/financeapp-4bNmUlQi-py3.8/lib/python3.8/site-packages/rest_framework/generics.py", line 221, in delete
    return self.destroy(request, *args, **kwargs)
  File "/home/igor/Documents/FinanceApp/api/views/categories.py", line 64, in destroy
    raise CategoryWithOperationsError(
api.views.errors.CategoryWithOperationsError: Can not delete category with existing operations.
2024-11-05 08:57:05,950 django.request WARNING log Bad Request: /api/v1/categories/8/
2024-11-05 08:58:32,052 django.request WARNING log Bad Request: /api/v1/categories/
2024-11-05 08:59:41,956 django.request WARNING log Bad Request: /api/v1/categories/
2024-11-05 09:00:57,995 django.request WARNING log Bad Request: /api/v1/categories/7/
2024-11-05 21:14:36,009 django.request WARNING log Bad Request: /api/v1/categories/7/
2024-11-05 21:15:05,030 django.request WARNING log Bad Request: /api/v1/categories/8/
2024-11-06 12:42:42,966 django.request ERROR log Internal Server Error: /api/v1/targets/
Traceback (most recent call last):
  File "/home/igor/.cache/pypoetry/virtualenvs/financeapp-4bNmUlQi-py3.8/lib/python3.8/site-packages/django/db/backends/utils.py", line 89, in _execute
    return self.cursor.execute(sql, params)
psycopg2.errors.UniqueViolation: duplicate key value violates unique constraint "targets_pkey"
DETAIL:  Key (id)=(1) already exists.


The above exception was the direct cause of the following exception:

Traceback (most recent call last):
  File "/home/igor/.cache/pypoetry/virtualenvs/financeapp-4bNmUlQi-py3.8/lib/python3.8/site-packages/django/core/handlers/exception.py", line 55, in inner
    response = get_response(request)
  File "/home/igor/.cache/pypoetry/virtualenvs/financeapp-4bNmUlQi-py3.8/lib/python3.8/site-packages/django/core/handlers/base.py", line 197, in _get_response
    response = wrapped_callback(request, *callback_args, **callback_kwargs)
  File "/home/igor/.cache/pypoetry/virtualenvs/financeapp-4bNmUlQi-py3.8/lib/python3.8/site-packages/django/views/decorators/csrf.py", line 56, in wrapper_view
    return view_func(*args, **kwargs)
  File "/home/igor/.cache/pypoetry/virtualenvs/financeapp-4bNmUlQi-py3.8/lib/python3.8/site-packages/django/views/generic/base.py", line 104, in view
    return self.dispatch(request, *args, **kwargs)
  File "/home/igor/.cache/pypoetry/virtualenvs/financeapp-4bNmUlQi-py3.8/lib/python3.8/site-packages/rest_framework/views.py", line 509, in dispatch
    response = self.handle_exception(exc)
  File "/home/igor/.cache/pypoetry/virtualenvs/financeapp-4bNmUlQi-py3.8/lib/python3.8/site-packages/rest_framework/views.py", line 469, in handle_exception
    self.raise_uncaught_exception(exc)
  File "/home/igor/.cache/pypoetry/virtualenvs/financeapp-4bNmUlQi-py3.8/lib/python3.8/site-packages/rest_framework/views.py", line 480, in raise_uncaught_exception
    raise exc
  File "/home/igor/.cache/pypoetry/virtualenvs/financeapp-4bNmUlQi-py3.8/lib/python3.8/site-packages/rest_framework/views.py", line 506, in dispatch
    response = handler(request, *args, **kwargs)
  File "/home/igor/.cache/pypoetry/virtualenvs/financeapp-4bNmUlQi-py3.8/lib/python3.8/site-packages/rest_framework/generics.py", line 246, in post
    return self.create(request, *args, **kwargs)
  File "/home/igor/.cache/pypoetry/virtualenvs/financeapp-4bNmUlQi-py3.8/lib/python3.8/site-packages/rest_framework/mixins.py", line 19, in create
    self.perform_create(serializer)
  File "/home/igor/.cache/pypoetry/virtualenvs/financeapp-4bNmUlQi-py3.8/lib/python3.8/site-packages/rest_framework/mixins.py", line 24, in perform_create
    serializer.save()
  File "/home/igor/.cache/pypoetry/virtualenvs/financeapp-4bNmUlQi-py3.8/lib/python3.8/site-packages/rest_framework/serializers.py", line 208, in save
    self.instance = self.create(validated_data)
  File "/home/igor/Documents/FinanceApp/api/serializers/target.py", line 27, in create
    return super().create(validated_data)
  File "/home/igor/.cache/pypoetry/virtualenvs/financeapp-4bNmUlQi-py3.8/lib/python3.8/site-packages/rest_framework/serializers.py", line 989, in create
    instance = ModelClass._default_manager.create(**validated_data)
  File "/home/igor/.cache/pypoetry/virtualenvs/financeapp-4bNmUlQi-py3.8/lib/python3.8/site-packages/django/db/models/manager.py", line 87, in manager_method
    return getattr(self.get_queryset(), name)(*args, **kwargs)
  File "/home/igor/.cache/pypoetry/virtualenvs/financeapp-4bNmUlQi-py3.8/lib/python3.8/site-packages/django/db/models/query.py", line 658, in create
    obj.save(force_insert=True, using=self.db)
  File "/home/igor/.cache/pypoetry/virtualenvs/financeapp-4bNmUlQi-py3.8/lib/python3.8/site-packages/django/db/models/base.py", line 814, in save
    self.save_base(
  File "/home/igor/.cache/pypoetry/virtualenvs/financeapp-4bNmUlQi-py3.8/lib/python3.8/site-packages/django/db/models/base.py", line 877, in save_base
    updated = self._save_table(
  File "/home/igor/.cache/pypoetry/virtualenvs/financeapp-4bNmUlQi-py3.8/lib/python3.8/site-packages/django/db/models/base.py", line 1020, in _save_table
    results = self._do_insert(
  File "/home/igor/.cache/pypoetry/virtualenvs/financeapp-4bNmUlQi-py3.8/lib/python3.8/site-packages/django/db/models/base.py", line 1061, in _do_insert
    return manager._insert(
  File "/home/igor/.cache/pypoetry/virtualenvs/financeapp-4bNmUlQi-py3.8/lib/python3.8/site-packages/django/db/models/manager.py", line 87, in manager_method
    return getattr(self.get_queryset(), name)(*args, **kwargs)
  File "/home/igor/.cache/pypoetry/virtualenvs/financeapp-4bNmUlQi-py3.8/lib/python3.8/site-packages/django/db/models/query.py", line 1805, in _insert
    return query.get_compiler(using=using).execute_sql(returning_fields)
  File "/home/igor/.cache/pypoetry/virtualenvs/financeapp-4bNmUlQi-py3.8/lib/python3.8/site-packages/django/db/models/sql/compiler.py", line 1822, in execute_sql
    cursor.execute(sql, params)
  File "/home/igor/.cache/pypoetry/virtualenvs/financeapp-4bNmUlQi-py3.8/lib/python3.8/site-packages/django/db/backends/utils.py", line 102, in execute
    return super().execute(sql, params)
  File "/home/igor/.cache/pypoetry/virtualenvs/financeapp-4bNmUlQi-py3.8/lib/python3.8/site-packages/django/db/backends/utils.py", line 67, in execute
    return self._execute_with_wrappers(
  File "/home/igor/.cache/pypoetry/virtualenvs/financeapp-4bNmUlQi-py3.8/lib/python3.8/site-packages/django/db/backends/utils.py", line 80, in _execute_with_wrappers
    return executor(sql, params, many, context)
  File "/home/igor/.cache/pypoetry/virtualenvs/financeapp-4bNmUlQi-py3.8/lib/python3.8/site-packages/django/db/backends/utils.py", line 89, in _execute
    return self.cursor.execute(sql, params)
  File "/home/igor/.cache/pypoetry/virtualenvs/financeapp-4bNmUlQi-py3.8/lib/python3.8/site-packages/django/db/utils.py", line 91, in __exit__
    raise dj_exc_value.with_traceback(traceback) from exc_value
  File "/home/igor/.cache/pypoetry/virtualenvs/financeapp-4bNmUlQi-py3.8/lib/python3.8/site-packages/django/db/backends/utils.py", line 89, in _execute
    return self.cursor.execute(sql, params)
django.db.utils.IntegrityError: duplicate key value violates unique constraint "targets_pkey"
DETAIL:  Key (id)=(1) already exists.

2024-11-06 12:43:24,820 django.request ERROR log Internal Server Error: /api/v1/targets/
Traceback (most recent call last):
  File "/home/igor/.cache/pypoetry/virtualenvs/financeapp-4bNmUlQi-py3.8/lib/python3.8/site-packages/django/db/backends/utils.py", line 89, in _execute
    return self.cursor.execute(sql, params)
psycopg2.errors.UniqueViolation: duplicate key value violates unique constraint "targets_pkey"
DETAIL:  Key (id)=(2) already exists.


The above exception was the direct cause of the following exception:

Traceback (most recent call last):
  File "/home/igor/.cache/pypoetry/virtualenvs/financeapp-4bNmUlQi-py3.8/lib/python3.8/site-packages/django/core/handlers/exception.py", line 55, in inner
    response = get_response(request)
  File "/home/igor/.cache/pypoetry/virtualenvs/financeapp-4bNmUlQi-py3.8/lib/python3.8/site-packages/django/core/handlers/base.py", line 197, in _get_response
    response = wrapped_callback(request, *callback_args, **callback_kwargs)
  File "/home/igor/.cache/pypoetry/virtualenvs/financeapp-4bNmUlQi-py3.8/lib/python3.8/site-packages/django/views/decorators/csrf.py", line 56, in wrapper_view
    return view_func(*args, **kwargs)
  File "/home/igor/.cache/pypoetry/virtualenvs/financeapp-4bNmUlQi-py3.8/lib/python3.8/site-packages/django/views/generic/base.py", line 104, in view
    return self.dispatch(request, *args, **kwargs)
  File "/home/igor/.cache/pypoetry/virtualenvs/financeapp-4bNmUlQi-py3.8/lib/python3.8/site-packages/rest_framework/views.py", line 509, in dispatch
    response = self.handle_exception(exc)
  File "/home/igor/.cache/pypoetry/virtualenvs/financeapp-4bNmUlQi-py3.8/lib/python3.8/site-packages/rest_framework/views.py", line 469, in handle_exception
    self.raise_uncaught_exception(exc)
  File "/home/igor/.cache/pypoetry/virtualenvs/financeapp-4bNmUlQi-py3.8/lib/python3.8/site-packages/rest_framework/views.py", line 480, in raise_uncaught_exception
    raise exc
  File "/home/igor/.cache/pypoetry/virtualenvs/financeapp-4bNmUlQi-py3.8/lib/python3.8/site-packages/rest_framework/views.py", line 506, in dispatch
    response = handler(request, *args, **kwargs)
  File "/home/igor/.cache/pypoetry/virtualenvs/financeapp-4bNmUlQi-py3.8/lib/python3.8/site-packages/rest_framework/generics.py", line 246, in post
    return self.create(request, *args, **kwargs)
  File "/home/igor/.cache/pypoetry/virtualenvs/financeapp-4bNmUlQi-py3.8/lib/python3.8/site-packages/rest_framework/mixins.py", line 19, in create
    self.perform_create(serializer)
  File "/home/igor/.cache/pypoetry/virtualenvs/financeapp-4bNmUlQi-py3.8/lib/python3.8/site-packages/rest_framework/mixins.py", line 24, in perform_create
    serializer.save()
  File "/home/igor/.cache/pypoetry/virtualenvs/financeapp-4bNmUlQi-py3.8/lib/python3.8/site-packages/rest_framework/serializers.py", line 208, in save
    self.instance = self.create(validated_data)
  File "/home/igor/Documents/FinanceApp/api/serializers/target.py", line 27, in create
    return super().create(validated_data)
  File "/home/igor/.cache/pypoetry/virtualenvs/financeapp-4bNmUlQi-py3.8/lib/python3.8/site-packages/rest_framework/serializers.py", line 989, in create
    instance = ModelClass._default_manager.create(**validated_data)
  File "/home/igor/.cache/pypoetry/virtualenvs/financeapp-4bNmUlQi-py3.8/lib/python3.8/site-packages/django/db/models/manager.py", line 87, in manager_method
    return getattr(self.get_queryset(), name)(*args, **kwargs)
  File "/home/igor/.cache/pypoetry/virtualenvs/financeapp-4bNmUlQi-py3.8/lib/python3.8/site-packages/django/db/models/query.py", line 658, in create
    obj.save(force_insert=True, using=self.db)
  File "/home/igor/.cache/pypoetry/virtualenvs/financeapp-4bNmUlQi-py3.8/lib/python3.8/site-packages/django/db/models/base.py", line 814, in save
    self.save_base(
  File "/home/igor/.cache/pypoetry/virtualenvs/financeapp-4bNmUlQi-py3.8/lib/python3.8/site-packages/django/db/models/base.py", line 877, in save_base
    updated = self._save_table(
  File "/home/igor/.cache/pypoetry/virtualenvs/financeapp-4bNmUlQi-py3.8/lib/python3.8/site-packages/django/db/models/base.py", line 1020, in _save_table
    results = self._do_insert(
  File "/home/igor/.cache/pypoetry/virtualenvs/financeapp-4bNmUlQi-py3.8/lib/python3.8/site-packages/django/db/models/base.py", line 1061, in _do_insert
    return manager._insert(
  File "/home/igor/.cache/pypoetry/virtualenvs/financeapp-4bNmUlQi-py3.8/lib/python3.8/site-packages/django/db/models/manager.py", line 87, in manager_method
    return getattr(self.get_queryset(), name)(*args, **kwargs)
  File "/home/igor/.cache/pypoetry/virtualenvs/financeapp-4bNmUlQi-py3.8/lib/python3.8/site-packages/django/db/models/query.py", line 1805, in _insert
    return query.get_compiler(using=using).execute_sql(returning_fields)
  File "/home/igor/.cache/pypoetry/virtualenvs/financeapp-4bNmUlQi-py3.8/lib/python3.8/site-packages/django/db/models/sql/compiler.py", line 1822, in execute_sql
    cursor.execute(sql, params)
  File "/home/igor/.cache/pypoetry/virtualenvs/financeapp-4bNmUlQi-py3.8/lib/python3.8/site-packages/django/db/backends/utils.py", line 102, in execute
    return super().execute(sql, params)
  File "/home/igor/.cache/pypoetry/virtualenvs/financeapp-4bNmUlQi-py3.8/lib/python3.8/site-packages/django/db/backends/utils.py", line 67, in execute
    return self._execute_with_wrappers(
  File "/home/igor/.cache/pypoetry/virtualenvs/financeapp-4bNmUlQi-py3.8/lib/python3.8/site-packages/django/db/backends/utils.py", line 80, in _execute_with_wrappers
    return executor(sql, params, many, context)
  File "/home/igor/.cache/pypoetry/virtualenvs/financeapp-4bNmUlQi-py3.8/lib/python3.8/site-packages/django/db/backends/utils.py", line 89, in _execute
    return self.cursor.execute(sql, params)
  File "/home/igor/.cache/pypoetry/virtualenvs/financeapp-4bNmUlQi-py3.8/lib/python3.8/site-packages/django/db/utils.py", line 91, in __exit__
    raise dj_exc_value.with_traceback(traceback) from exc_value
  File "/home/igor/.cache/pypoetry/virtualenvs/financeapp-4bNmUlQi-py3.8/lib/python3.8/site-packages/django/db/backends/utils.py", line 89, in _execute
    return self.cursor.execute(sql, params)
django.db.utils.IntegrityError: duplicate key value violates unique constraint "targets_pkey"
DETAIL:  Key (id)=(2) already exists.

2024-11-06 12:46:07,351 django.request WARNING log Bad Request: /api/v1/targets/2/
2024-11-11 11:00:22,668 django.request WARNING log Method Not Allowed: /api/v1/targets/3/
2024-11-11 12:37:07,479 django.request WARNING log Method Not Allowed: /api/v1/targets/2/return_money/
2024-11-11 12:39:00,401 django.request ERROR log Internal Server Error: /api/v1/targets/4/return_money/
Traceback (most recent call last):
  File "/home/igor/.cache/pypoetry/virtualenvs/financeapp-4bNmUlQi-py3.8/lib/python3.8/site-packages/django/core/handlers/exception.py", line 55, in inner
    response = get_response(request)
  File "/home/igor/.cache/pypoetry/virtualenvs/financeapp-4bNmUlQi-py3.8/lib/python3.8/site-packages/django/core/handlers/base.py", line 197, in _get_response
    response = wrapped_callback(request, *callback_args, **callback_kwargs)
  File "/home/igor/.cache/pypoetry/virtualenvs/financeapp-4bNmUlQi-py3.8/lib/python3.8/site-packages/django/views/decorators/csrf.py", line 56, in wrapper_view
    return view_func(*args, **kwargs)
  File "/home/igor/.cache/pypoetry/virtualenvs/financeapp-4bNmUlQi-py3.8/lib/python3.8/site-packages/django/views/generic/base.py", line 104, in view
    return self.dispatch(request, *args, **kwargs)
  File "/home/igor/.cache/pypoetry/virtualenvs/financeapp-4bNmUlQi-py3.8/lib/python3.8/site-packages/rest_framework/views.py", line 509, in dispatch
    response = self.handle_exception(exc)
  File "/home/igor/.cache/pypoetry/virtualenvs/financeapp-4bNmUlQi-py3.8/lib/python3.8/site-packages/rest_framework/views.py", line 469, in handle_exception
    self.raise_uncaught_exception(exc)
  File "/home/igor/.cache/pypoetry/virtualenvs/financeapp-4bNmUlQi-py3.8/lib/python3.8/site-packages/rest_framework/views.py", line 480, in raise_uncaught_exception
    raise exc
  File "/home/igor/.cache/pypoetry/virtualenvs/financeapp-4bNmUlQi-py3.8/lib/python3.8/site-packages/rest_framework/views.py", line 506, in dispatch
    response = handler(request, *args, **kwargs)
  File "/home/igor/Documents/FinanceApp/api/views/targets.py", line 89, in patch
    category = Category.objects.create(
  File "/home/igor/.cache/pypoetry/virtualenvs/financeapp-4bNmUlQi-py3.8/lib/python3.8/site-packages/django/db/models/manager.py", line 87, in manager_method
    return getattr(self.get_queryset(), name)(*args, **kwargs)
  File "/home/igor/.cache/pypoetry/virtualenvs/financeapp-4bNmUlQi-py3.8/lib/python3.8/site-packages/django/db/models/query.py", line 656, in create
    obj = self.model(**kwargs)
  File "/home/igor/.cache/pypoetry/virtualenvs/financeapp-4bNmUlQi-py3.8/lib/python3.8/site-packages/django/db/models/base.py", line 543, in __init__
    _setattr(self, field.name, rel_obj)
  File "/home/igor/.cache/pypoetry/virtualenvs/financeapp-4bNmUlQi-py3.8/lib/python3.8/site-packages/django/db/models/fields/related_descriptors.py", line 266, in __set__
    raise ValueError(
ValueError: Cannot assign "1": "Category.user" must be a "User" instance.
2024-11-11 12:39:34,736 django.request ERROR log Internal Server Error: /api/v1/targets/4/return_money/
Traceback (most recent call last):
  File "/home/igor/.cache/pypoetry/virtualenvs/financeapp-4bNmUlQi-py3.8/lib/python3.8/site-packages/django/core/handlers/exception.py", line 55, in inner
    response = get_response(request)
  File "/home/igor/.cache/pypoetry/virtualenvs/financeapp-4bNmUlQi-py3.8/lib/python3.8/site-packages/django/core/handlers/base.py", line 197, in _get_response
    response = wrapped_callback(request, *callback_args, **callback_kwargs)
  File "/home/igor/.cache/pypoetry/virtualenvs/financeapp-4bNmUlQi-py3.8/lib/python3.8/site-packages/django/views/decorators/csrf.py", line 56, in wrapper_view
    return view_func(*args, **kwargs)
  File "/home/igor/.cache/pypoetry/virtualenvs/financeapp-4bNmUlQi-py3.8/lib/python3.8/site-packages/django/views/generic/base.py", line 104, in view
    return self.dispatch(request, *args, **kwargs)
  File "/home/igor/.cache/pypoetry/virtualenvs/financeapp-4bNmUlQi-py3.8/lib/python3.8/site-packages/rest_framework/views.py", line 509, in dispatch
    response = self.handle_exception(exc)
  File "/home/igor/.cache/pypoetry/virtualenvs/financeapp-4bNmUlQi-py3.8/lib/python3.8/site-packages/rest_framework/views.py", line 469, in handle_exception
    self.raise_uncaught_exception(exc)
  File "/home/igor/.cache/pypoetry/virtualenvs/financeapp-4bNmUlQi-py3.8/lib/python3.8/site-packages/rest_framework/views.py", line 480, in raise_uncaught_exception
    raise exc
  File "/home/igor/.cache/pypoetry/virtualenvs/financeapp-4bNmUlQi-py3.8/lib/python3.8/site-packages/rest_framework/views.py", line 506, in dispatch
    response = handler(request, *args, **kwargs)
  File "/home/igor/Documents/FinanceApp/api/views/targets.py", line 89, in patch
    category = Category.objects.create(
  File "/home/igor/.cache/pypoetry/virtualenvs/financeapp-4bNmUlQi-py3.8/lib/python3.8/site-packages/django/db/models/manager.py", line 87, in manager_method
    return getattr(self.get_queryset(), name)(*args, **kwargs)
  File "/home/igor/.cache/pypoetry/virtualenvs/financeapp-4bNmUlQi-py3.8/lib/python3.8/site-packages/django/db/models/query.py", line 656, in create
    obj = self.model(**kwargs)
  File "/home/igor/.cache/pypoetry/virtualenvs/financeapp-4bNmUlQi-py3.8/lib/python3.8/site-packages/django/db/models/base.py", line 543, in __init__
    _setattr(self, field.name, rel_obj)
  File "/home/igor/.cache/pypoetry/virtualenvs/financeapp-4bNmUlQi-py3.8/lib/python3.8/site-packages/django/db/models/fields/related_descriptors.py", line 266, in __set__
    raise ValueError(
ValueError: Cannot assign "1": "Category.user" must be a "User" instance.
2024-11-11 12:41:22,918 django.request ERROR log Internal Server Error: /api/v1/targets/4/return_money/
Traceback (most recent call last):
  File "/home/igor/.cache/pypoetry/virtualenvs/financeapp-4bNmUlQi-py3.8/lib/python3.8/site-packages/django/core/handlers/exception.py", line 55, in inner
    response = get_response(request)
  File "/home/igor/.cache/pypoetry/virtualenvs/financeapp-4bNmUlQi-py3.8/lib/python3.8/site-packages/django/core/handlers/base.py", line 197, in _get_response
    response = wrapped_callback(request, *callback_args, **callback_kwargs)
  File "/home/igor/.cache/pypoetry/virtualenvs/financeapp-4bNmUlQi-py3.8/lib/python3.8/site-packages/django/views/decorators/csrf.py", line 56, in wrapper_view
    return view_func(*args, **kwargs)
  File "/home/igor/.cache/pypoetry/virtualenvs/financeapp-4bNmUlQi-py3.8/lib/python3.8/site-packages/django/views/generic/base.py", line 104, in view
    return self.dispatch(request, *args, **kwargs)
  File "/home/igor/.cache/pypoetry/virtualenvs/financeapp-4bNmUlQi-py3.8/lib/python3.8/site-packages/rest_framework/views.py", line 509, in dispatch
    response = self.handle_exception(exc)
  File "/home/igor/.cache/pypoetry/virtualenvs/financeapp-4bNmUlQi-py3.8/lib/python3.8/site-packages/rest_framework/views.py", line 469, in handle_exception
    self.raise_uncaught_exception(exc)
  File "/home/igor/.cache/pypoetry/virtualenvs/financeapp-4bNmUlQi-py3.8/lib/python3.8/site-packages/rest_framework/views.py", line 480, in raise_uncaught_exception
    raise exc
  File "/home/igor/.cache/pypoetry/virtualenvs/financeapp-4bNmUlQi-py3.8/lib/python3.8/site-packages/rest_framework/views.py", line 506, in dispatch
    response = handler(request, *args, **kwargs)
  File "/home/igor/Documents/FinanceApp/api/views/targets.py", line 95, in patch
    Operation.objects.create(
  File "/home/igor/.cache/pypoetry/virtualenvs/financeapp-4bNmUlQi-py3.8/lib/python3.8/site-packages/django/db/models/manager.py", line 87, in manager_method
    return getattr(self.get_queryset(), name)(*args, **kwargs)
  File "/home/igor/.cache/pypoetry/virtualenvs/financeapp-4bNmUlQi-py3.8/lib/python3.8/site-packages/django/db/models/query.py", line 656, in create
    obj = self.model(**kwargs)
  File "/home/igor/.cache/pypoetry/virtualenvs/financeapp-4bNmUlQi-py3.8/lib/python3.8/site-packages/django/db/models/base.py", line 567, in __init__
    raise TypeError(
TypeError: Operation() got unexpected keyword arguments: 'category'
2024-11-11 12:42:03,390 django.request WARNING log Bad Request: /api/v1/targets/4/return_money/
2024-11-11 13:38:04,065 django.request ERROR log Internal Server Error: /api/v1/targets/4/return_money/
Traceback (most recent call last):
  File "/home/igor/.cache/pypoetry/virtualenvs/financeapp-4bNmUlQi-py3.8/lib/python3.8/site-packages/django/core/handlers/exception.py", line 55, in inner
    response = get_response(request)
  File "/home/igor/.cache/pypoetry/virtualenvs/financeapp-4bNmUlQi-py3.8/lib/python3.8/site-packages/django/core/handlers/base.py", line 197, in _get_response
    response = wrapped_callback(request, *callback_args, **callback_kwargs)
  File "/home/igor/.cache/pypoetry/virtualenvs/financeapp-4bNmUlQi-py3.8/lib/python3.8/site-packages/django/views/decorators/csrf.py", line 56, in wrapper_view
    return view_func(*args, **kwargs)
  File "/home/igor/.cache/pypoetry/virtualenvs/financeapp-4bNmUlQi-py3.8/lib/python3.8/site-packages/django/views/generic/base.py", line 104, in view
    return self.dispatch(request, *args, **kwargs)
  File "/home/igor/.cache/pypoetry/virtualenvs/financeapp-4bNmUlQi-py3.8/lib/python3.8/site-packages/rest_framework/views.py", line 509, in dispatch
    response = self.handle_exception(exc)
  File "/home/igor/.cache/pypoetry/virtualenvs/financeapp-4bNmUlQi-py3.8/lib/python3.8/site-packages/rest_framework/views.py", line 469, in handle_exception
    self.raise_uncaught_exception(exc)
  File "/home/igor/.cache/pypoetry/virtualenvs/financeapp-4bNmUlQi-py3.8/lib/python3.8/site-packages/rest_framework/views.py", line 480, in raise_uncaught_exception
    raise exc
  File "/home/igor/.cache/pypoetry/virtualenvs/financeapp-4bNmUlQi-py3.8/lib/python3.8/site-packages/rest_framework/views.py", line 506, in dispatch
    response = handler(request, *args, **kwargs)
  File "/home/igor/Documents/FinanceApp/api/views/targets.py", line 89, in patch
    category = Category.objects.get_or_create(
  File "/home/igor/.cache/pypoetry/virtualenvs/financeapp-4bNmUlQi-py3.8/lib/python3.8/site-packages/django/db/models/manager.py", line 87, in manager_method
    return getattr(self.get_queryset(), name)(*args, **kwargs)
  File "/home/igor/.cache/pypoetry/virtualenvs/financeapp-4bNmUlQi-py3.8/lib/python3.8/site-packages/django/db/models/query.py", line 916, in get_or_create
    return self.get(**kwargs), False
  File "/home/igor/.cache/pypoetry/virtualenvs/financeapp-4bNmUlQi-py3.8/lib/python3.8/site-packages/django/db/models/query.py", line 640, in get
    raise self.model.MultipleObjectsReturned(
api.models.category.Category.MultipleObjectsReturned: get() returned more than one Category -- it returned 2!
2024-11-11 13:40:36,220 django.request ERROR log Internal Server Error: /api/v1/targets/4/return_money/
Traceback (most recent call last):
  File "/home/igor/.cache/pypoetry/virtualenvs/financeapp-4bNmUlQi-py3.8/lib/python3.8/site-packages/django/core/handlers/exception.py", line 55, in inner
    response = get_response(request)
  File "/home/igor/.cache/pypoetry/virtualenvs/financeapp-4bNmUlQi-py3.8/lib/python3.8/site-packages/django/core/handlers/base.py", line 197, in _get_response
    response = wrapped_callback(request, *callback_args, **callback_kwargs)
  File "/home/igor/.cache/pypoetry/virtualenvs/financeapp-4bNmUlQi-py3.8/lib/python3.8/site-packages/django/views/decorators/csrf.py", line 56, in wrapper_view
    return view_func(*args, **kwargs)
  File "/home/igor/.cache/pypoetry/virtualenvs/financeapp-4bNmUlQi-py3.8/lib/python3.8/site-packages/django/views/generic/base.py", line 104, in view
    return self.dispatch(request, *args, **kwargs)
  File "/home/igor/.cache/pypoetry/virtualenvs/financeapp-4bNmUlQi-py3.8/lib/python3.8/site-packages/rest_framework/views.py", line 509, in dispatch
    response = self.handle_exception(exc)
  File "/home/igor/.cache/pypoetry/virtualenvs/financeapp-4bNmUlQi-py3.8/lib/python3.8/site-packages/rest_framework/views.py", line 469, in handle_exception
    self.raise_uncaught_exception(exc)
  File "/home/igor/.cache/pypoetry/virtualenvs/financeapp-4bNmUlQi-py3.8/lib/python3.8/site-packages/rest_framework/views.py", line 480, in raise_uncaught_exception
    raise exc
  File "/home/igor/.cache/pypoetry/virtualenvs/financeapp-4bNmUlQi-py3.8/lib/python3.8/site-packages/rest_framework/views.py", line 506, in dispatch
    response = handler(request, *args, **kwargs)
  File "/home/igor/Documents/FinanceApp/api/views/targets.py", line 95, in patch
    Operation.objects.create(
  File "/home/igor/.cache/pypoetry/virtualenvs/financeapp-4bNmUlQi-py3.8/lib/python3.8/site-packages/django/db/models/manager.py", line 87, in manager_method
    return getattr(self.get_queryset(), name)(*args, **kwargs)
  File "/home/igor/.cache/pypoetry/virtualenvs/financeapp-4bNmUlQi-py3.8/lib/python3.8/site-packages/django/db/models/query.py", line 656, in create
    obj = self.model(**kwargs)
  File "/home/igor/.cache/pypoetry/virtualenvs/financeapp-4bNmUlQi-py3.8/lib/python3.8/site-packages/django/db/models/base.py", line 543, in __init__
    _setattr(self, field.name, rel_obj)
  File "/home/igor/.cache/pypoetry/virtualenvs/financeapp-4bNmUlQi-py3.8/lib/python3.8/site-packages/django/db/models/fields/related_descriptors.py", line 266, in __set__
    raise ValueError(
ValueError: Cannot assign "(<Category: из накоплений>, False)": "Operation.categories" must be a "Category" instance.
2024-11-11 14:10:49,713 django.request WARNING log Bad Request: /api/v1/targets/4/return_money/
2024-11-12 11:17:15,216 django.request ERROR log Internal Server Error: /api/v1/targets/5/
Traceback (most recent call last):
  File "/home/igor/.cache/pypoetry/virtualenvs/financeapp-4bNmUlQi-py3.8/lib/python3.8/site-packages/django/core/handlers/exception.py", line 55, in inner
    response = get_response(request)
  File "/home/igor/.cache/pypoetry/virtualenvs/financeapp-4bNmUlQi-py3.8/lib/python3.8/site-packages/django/core/handlers/base.py", line 197, in _get_response
    response = wrapped_callback(request, *callback_args, **callback_kwargs)
  File "/home/igor/.cache/pypoetry/virtualenvs/financeapp-4bNmUlQi-py3.8/lib/python3.8/site-packages/django/views/decorators/csrf.py", line 56, in wrapper_view
    return view_func(*args, **kwargs)
  File "/home/igor/.cache/pypoetry/virtualenvs/financeapp-4bNmUlQi-py3.8/lib/python3.8/site-packages/django/views/generic/base.py", line 104, in view
    return self.dispatch(request, *args, **kwargs)
  File "/home/igor/.cache/pypoetry/virtualenvs/financeapp-4bNmUlQi-py3.8/lib/python3.8/site-packages/rest_framework/views.py", line 509, in dispatch
    response = self.handle_exception(exc)
  File "/home/igor/.cache/pypoetry/virtualenvs/financeapp-4bNmUlQi-py3.8/lib/python3.8/site-packages/rest_framework/views.py", line 469, in handle_exception
    self.raise_uncaught_exception(exc)
  File "/home/igor/.cache/pypoetry/virtualenvs/financeapp-4bNmUlQi-py3.8/lib/python3.8/site-packages/rest_framework/views.py", line 480, in raise_uncaught_exception
    raise exc
  File "/home/igor/.cache/pypoetry/virtualenvs/financeapp-4bNmUlQi-py3.8/lib/python3.8/site-packages/rest_framework/views.py", line 506, in dispatch
    response = handler(request, *args, **kwargs)
  File "/home/igor/.cache/pypoetry/virtualenvs/financeapp-4bNmUlQi-py3.8/lib/python3.8/site-packages/rest_framework/generics.py", line 221, in delete
    return self.destroy(request, *args, **kwargs)
  File "/home/igor/Documents/FinanceApp/api/views/targets.py", line 69, in destroy
    isinstance.is_deleted = True
AttributeError: 'builtin_function_or_method' object has no attribute 'is_deleted'
2024-11-12 11:27:23,382 django.request WARNING log Bad Request: /api/v1/targets/5/
2024-11-12 11:28:52,763 django.request WARNING log Bad Request: /api/v1/targets/5/
2024-11-12 11:29:06,380 django.request WARNING log Bad Request: /api/v1/targets/5/
2024-11-12 11:33:59,405 django.request WARNING log Bad Request: /api/v1/targets/5/return_money/
2024-11-12 12:09:20,095 django.request WARNING log Bad Request: /api/v1/targets/4/
2024-11-12 13:14:22,903 django.request WARNING log Bad Request: /api/v1/operations/
2024-11-12 13:15:16,445 django.request WARNING log Bad Request: /api/v1/operations/
2024-11-12 13:28:10,988 django.request WARNING log Bad Request: /api/v1/targets/5/return_money/
2024-11-12 21:41:04,801 django.request WARNING log Bad Request: /api/v1/auth/users/
2024-11-12 21:41:17,010 django.request WARNING log Bad Request: /api/v1/auth/users/
2024-11-12 21:43:19,366 django.request WARNING log Not Found: /api/v1/schema/swagger-ui/auth/auth_users_create
2024-11-12 21:43:19,659 django.request WARNING log Not Found: /favicon.ico
2024-11-12 21:44:44,767 django.request WARNING log Bad Request: /api/v1/auth/users/
2024-11-12 21:45:05,687 django.request WARNING log Bad Request: /api/v1/auth/users/
